Traceback (most recent call last):
  File "/home/s/Documents/source/callback-verification/cbverifier/driver.py", line 466, in <module>
    main()
  File "/home/s/Documents/source/callback-verification/cbverifier/driver.py", line 390, in main
    driver = Driver(driver_opts)
MemoryError
real 35.81
user 32.75
sys 3.02
