/usr/lib/python2.7/pkgutil.py:186: ImportWarning: Not importing directory '/usr/local/lib/python2.7/dist-packages/google': missing __init__.py
  file, filename, etc = imp.find_module(subname, path)
/usr/lib/python2.7/pkgutil.py:186: ImportWarning: Not importing directory '/usr/local/lib/python2.7/dist-packages/mpl_toolkits': missing __init__.py
  file, filename, etc = imp.find_module(subname, path)
Traceback (most recent call last):
  File "/home/s/Documents/source/callback-verification/cbverifier/driver.py", line 53, in __init__
    self.opts.allow_exception)
  File "/home/s/Documents/source/callback-verification/cbverifier/traces/ctrace.py", line 497, in read_trace_file_name
    allow_exception)
  File "/home/s/Documents/source/callback-verification/cbverifier/traces/ctrace.py", line 515, in read_trace
    allow_exception)
  File "/home/s/Documents/source/callback-verification/cbverifier/traces/ctrace.py", line 578, in read_trace_inner
    assert (isinstance(trace_message, CCallback))
AssertionError
/home/s/Documents/source/callback-verification/cbverifier/driver.py:62: DeprecationWarning: BaseException.message has been deprecated as of Python 2.6
  e.message))
Traceback (most recent call last):
  File "/home/s/Documents/source/callback-verification/cbverifier/driver.py", line 414, in <module>
    main()
  File "/home/s/Documents/source/callback-verification/cbverifier/driver.py", line 343, in main
    driver = Driver(driver_opts)
  File "/home/s/Documents/source/callback-verification/cbverifier/driver.py", line 62, in __init__
    e.message))
Exception: An error happened reading the trace in /home/s/Documents/data/monkey_traces/output/smblott-github-intent_radio-bin/monkeyTraces/trace_2017-04-07_14:31:31 ()
real 1.11
user 1.08
sys 0.02
