/home/s/Documents/source/callback-verification/cbverifier/driver.py:66: DeprecationWarning: BaseException.message has been deprecated as of Python 2.6
  e.message))
Traceback (most recent call last):
  File "/home/s/Documents/source/callback-verification/cbverifier/driver.py", line 466, in <module>
    main()
  File "/home/s/Documents/source/callback-verification/cbverifier/driver.py", line 390, in main
    driver = Driver(driver_opts)
  File "/home/s/Documents/source/callback-verification/cbverifier/driver.py", line 66, in __init__
    e.message))
Exception: An error happened reading the trace in /home/ubuntu/Documents/data/monkey_traces/alert-dialog-traces-2/_traces/RossMeikleham-PlutoBoy-main/monkeyTraces/trace-SDLActivity-debug-unaligned_2017-04-16_18:30:01.repaired (pop from empty list)
real 0.32
user 0.25
sys 0.05
