/home/s/Documents/source/callback-verification/cbverifier/driver.py:66: DeprecationWarning: BaseException.message has been deprecated as of Python 2.6
  e.message))
Traceback (most recent call last):
  File "/home/s/Documents/source/callback-verification/cbverifier/driver.py", line 466, in <module>
    main()
  File "/home/s/Documents/source/callback-verification/cbverifier/driver.py", line 390, in main
    driver = Driver(driver_opts)
  File "/home/s/Documents/source/callback-verification/cbverifier/driver.py", line 66, in __init__
    e.message))
Exception: An error happened reading the trace in /home/ubuntu/Documents/data/monkey_traces/output/Kistenstapeln-fix/monkeyTraces/trace_2017-03-29_19:32:31.repaired ()
real 0.73
user 0.64
sys 0.07
