/home/s/Documents/source/callback-verification/cbverifier/driver.py:66: DeprecationWarning: BaseException.message has been deprecated as of Python 2.6
  e.message))
Traceback (most recent call last):
  File "/home/s/Documents/source/callback-verification/cbverifier/driver.py", line 437, in <module>
    main()
  File "/home/s/Documents/source/callback-verification/cbverifier/driver.py", line 366, in main
    driver = Driver(driver_opts)
  File "/home/s/Documents/source/callback-verification/cbverifier/driver.py", line 66, in __init__
    e.message))
Exception: An error happened reading the trace in /home/ubuntu/Documents/data/apps_man_corp/com.uberspot.a2048/23/traces/manual31.trace.repaired ()
real 3.99
user 3.63
sys 0.28
