Traceback (most recent call last):
  File "/home/ubuntu/Documents/source/callback-verification/cbverifier/driver.py", line 502, in <module>
    main()
  File "/home/ubuntu/Documents/source/callback-verification/cbverifier/driver.py", line 409, in main
    driver = Driver(driver_opts)
  File "/home/ubuntu/Documents/source/callback-verification/cbverifier/driver.py", line 62, in __init__
    self.opts.allow_exception)
  File "/home/ubuntu/Documents/source/callback-verification/cbverifier/traces/ctrace.py", line 649, in read_trace_file_name
    allow_exception)
  File "/home/ubuntu/Documents/source/callback-verification/cbverifier/traces/ctrace.py", line 667, in read_trace
    allow_exception)
  File "/home/ubuntu/Documents/source/callback-verification/cbverifier/traces/ctrace.py", line 738, in read_trace_inner
    raise MalformedTraceException("The number of entry messages does " \
cbverifier.traces.ctrace.MalformedTraceException: The number of entry messages does match the number of exit/exception messages.
real 0.59
user 0.48
sys 0.06
